[2023-06-15T16:12:13.302+0000] {taskinstance.py:1103} INFO - Dependencies all met for dep_context=non-requeueable deps ti=<TaskInstance: gcs_2_bq_dag.bq_2020_tripdata_external_table_task manual__2023-06-15T16:12:11.215987+00:00 [queued]>
[2023-06-15T16:12:13.317+0000] {taskinstance.py:1103} INFO - Dependencies all met for dep_context=requeueable deps ti=<TaskInstance: gcs_2_bq_dag.bq_2020_tripdata_external_table_task manual__2023-06-15T16:12:11.215987+00:00 [queued]>
[2023-06-15T16:12:13.318+0000] {taskinstance.py:1308} INFO - Starting attempt 1 of 2
[2023-06-15T16:12:13.332+0000] {taskinstance.py:1327} INFO - Executing <Task(BigQueryCreateExternalTableOperator): bq_2020_tripdata_external_table_task> on 2023-06-15 16:12:11.215987+00:00
[2023-06-15T16:12:13.342+0000] {standard_task_runner.py:57} INFO - Started process 1793 to run task
[2023-06-15T16:12:13.346+0000] {standard_task_runner.py:84} INFO - Running: ['***', 'tasks', 'run', 'gcs_2_bq_dag', 'bq_2020_tripdata_external_table_task', 'manual__2023-06-15T16:12:11.215987+00:00', '--job-id', '507', '--raw', '--subdir', 'DAGS_FOLDER/gcs_to_bq.py', '--cfg-path', '/tmp/tmptbdxvat1']
[2023-06-15T16:12:13.348+0000] {standard_task_runner.py:85} INFO - Job 507: Subtask bq_2020_tripdata_external_table_task
[2023-06-15T16:12:13.421+0000] {task_command.py:410} INFO - Running <TaskInstance: gcs_2_bq_dag.bq_2020_tripdata_external_table_task manual__2023-06-15T16:12:11.215987+00:00 [running]> on host 659e337ed365
[2023-06-15T16:12:13.529+0000] {taskinstance.py:1545} INFO - Exporting env vars: AIRFLOW_CTX_DAG_OWNER='***' AIRFLOW_CTX_DAG_ID='gcs_2_bq_dag' AIRFLOW_CTX_TASK_ID='bq_2020_tripdata_external_table_task' AIRFLOW_CTX_EXECUTION_DATE='2023-06-15T16:12:11.215987+00:00' AIRFLOW_CTX_TRY_NUMBER='1' AIRFLOW_CTX_DAG_RUN_ID='manual__2023-06-15T16:12:11.215987+00:00'
[2023-06-15T16:12:13.552+0000] {base.py:73} INFO - Using connection ID 'gcloud' for task execution.
[2023-06-15T16:12:15.654+0000] {taskinstance.py:1824} ERROR - Task failed with exception
Traceback (most recent call last):
  File "/home/airflow/.local/lib/python3.9/site-packages/airflow/providers/google/cloud/operators/bigquery.py", line 1612, in execute
    table = bq_hook.create_empty_table(
  File "/home/airflow/.local/lib/python3.9/site-packages/airflow/providers/google/common/hooks/base_google.py", line 468, in inner_wrapper
    return func(self, *args, **kwargs)
  File "/home/airflow/.local/lib/python3.9/site-packages/airflow/providers/google/cloud/hooks/bigquery.py", line 406, in create_empty_table
    return self.get_client(project_id=project_id, location=location).create_table(
  File "/home/airflow/.local/lib/python3.9/site-packages/google/cloud/bigquery/client.py", line 748, in create_table
    api_response = self._call_api(
  File "/home/airflow/.local/lib/python3.9/site-packages/google/cloud/bigquery/client.py", line 782, in _call_api
    return call()
  File "/home/airflow/.local/lib/python3.9/site-packages/google/api_core/retry.py", line 283, in retry_wrapped_func
    return retry_target(
  File "/home/airflow/.local/lib/python3.9/site-packages/google/api_core/retry.py", line 190, in retry_target
    return target()
  File "/home/airflow/.local/lib/python3.9/site-packages/google/cloud/_http/__init__.py", line 494, in api_request
    raise exceptions.from_http_response(response)
google.api_core.exceptions.BadRequest: 400 POST https://bigquery.googleapis.com/bigquery/v2/projects/dtc-de-382609/datasets/stock_table/tables?prettyPrint=false: Error while reading table: 2020_tripdata_external_table, error message: Failed to expand table 2020_tripdata_external_table with file pattern gs://dtc-de-382609_bucket/stock_data/2020/*: matched no files. File: gs://dtc-de-382609_bucket/stock_data/2020/*
[2023-06-15T16:12:15.665+0000] {taskinstance.py:1345} INFO - Marking task as UP_FOR_RETRY. dag_id=gcs_2_bq_dag, task_id=bq_2020_tripdata_external_table_task, execution_date=20230615T161211, start_date=20230615T161213, end_date=20230615T161215
[2023-06-15T16:12:15.681+0000] {standard_task_runner.py:104} ERROR - Failed to execute job 507 for task bq_2020_tripdata_external_table_task (400 POST https://bigquery.googleapis.com/bigquery/v2/projects/dtc-de-382609/datasets/stock_table/tables?prettyPrint=false: Error while reading table: 2020_tripdata_external_table, error message: Failed to expand table 2020_tripdata_external_table with file pattern gs://dtc-de-382609_bucket/stock_data/2020/*: matched no files. File: gs://dtc-de-382609_bucket/stock_data/2020/*; 1793)
[2023-06-15T16:12:15.730+0000] {local_task_job_runner.py:225} INFO - Task exited with return code 1
[2023-06-15T16:12:15.747+0000] {taskinstance.py:2651} INFO - 0 downstream tasks scheduled from follow-on schedule check
