[2023-06-15T14:14:43.194+0000] {taskinstance.py:1103} INFO - Dependencies all met for dep_context=non-requeueable deps ti=<TaskInstance: gcs_2_bq_dag.bq_2022_tripdata_external_table_task scheduled__2023-06-14T00:00:00+00:00 [queued]>
[2023-06-15T14:14:43.213+0000] {taskinstance.py:1103} INFO - Dependencies all met for dep_context=requeueable deps ti=<TaskInstance: gcs_2_bq_dag.bq_2022_tripdata_external_table_task scheduled__2023-06-14T00:00:00+00:00 [queued]>
[2023-06-15T14:14:43.213+0000] {taskinstance.py:1308} INFO - Starting attempt 2 of 2
[2023-06-15T14:14:43.233+0000] {taskinstance.py:1327} INFO - Executing <Task(BigQueryCreateExternalTableOperator): bq_2022_tripdata_external_table_task> on 2023-06-14 00:00:00+00:00
[2023-06-15T14:14:43.242+0000] {standard_task_runner.py:57} INFO - Started process 146 to run task
[2023-06-15T14:14:43.249+0000] {standard_task_runner.py:84} INFO - Running: ['***', 'tasks', 'run', 'gcs_2_bq_dag', 'bq_2022_tripdata_external_table_task', 'scheduled__2023-06-14T00:00:00+00:00', '--job-id', '479', '--raw', '--subdir', 'DAGS_FOLDER/gcs_to_bq.py', '--cfg-path', '/tmp/tmpnk1q1153']
[2023-06-15T14:14:43.253+0000] {standard_task_runner.py:85} INFO - Job 479: Subtask bq_2022_tripdata_external_table_task
[2023-06-15T14:14:43.320+0000] {task_command.py:410} INFO - Running <TaskInstance: gcs_2_bq_dag.bq_2022_tripdata_external_table_task scheduled__2023-06-14T00:00:00+00:00 [running]> on host 659e337ed365
[2023-06-15T14:14:43.464+0000] {taskinstance.py:1545} INFO - Exporting env vars: AIRFLOW_CTX_DAG_OWNER='***' AIRFLOW_CTX_DAG_ID='gcs_2_bq_dag' AIRFLOW_CTX_TASK_ID='bq_2022_tripdata_external_table_task' AIRFLOW_CTX_EXECUTION_DATE='2023-06-14T00:00:00+00:00' AIRFLOW_CTX_TRY_NUMBER='2' AIRFLOW_CTX_DAG_RUN_ID='scheduled__2023-06-14T00:00:00+00:00'
[2023-06-15T14:14:43.488+0000] {taskinstance.py:1824} ERROR - Task failed with exception
Traceback (most recent call last):
  File "/home/airflow/.local/lib/python3.9/site-packages/airflow/providers/google/cloud/operators/bigquery.py", line 1606, in execute
    bq_hook = BigQueryHook(
  File "/home/airflow/.local/lib/python3.9/site-packages/airflow/providers/google/cloud/hooks/bigquery.py", line 105, in __init__
    super().__init__(
  File "/home/airflow/.local/lib/python3.9/site-packages/airflow/providers/google/common/hooks/base_google.py", line 234, in __init__
    self.extras: dict = self.get_connection(self.gcp_conn_id).extra_dejson
  File "/home/airflow/.local/lib/python3.9/site-packages/airflow/hooks/base.py", line 72, in get_connection
    conn = Connection.get_connection_from_secrets(conn_id)
  File "/home/airflow/.local/lib/python3.9/site-packages/airflow/models/connection.py", line 434, in get_connection_from_secrets
    raise AirflowNotFoundException(f"The conn_id `{conn_id}` isn't defined")
airflow.exceptions.AirflowNotFoundException: The conn_id `google_cloud_default` isn't defined
[2023-06-15T14:14:43.495+0000] {taskinstance.py:1345} INFO - Marking task as FAILED. dag_id=gcs_2_bq_dag, task_id=bq_2022_tripdata_external_table_task, execution_date=20230614T000000, start_date=20230615T141443, end_date=20230615T141443
[2023-06-15T14:14:43.510+0000] {standard_task_runner.py:104} ERROR - Failed to execute job 479 for task bq_2022_tripdata_external_table_task (The conn_id `google_cloud_default` isn't defined; 146)
[2023-06-15T14:14:43.538+0000] {local_task_job_runner.py:225} INFO - Task exited with return code 1
[2023-06-15T14:14:43.559+0000] {taskinstance.py:2651} INFO - 0 downstream tasks scheduled from follow-on schedule check
[2023-06-15T15:26:34.024+0000] {taskinstance.py:1103} INFO - Dependencies all met for dep_context=non-requeueable deps ti=<TaskInstance: gcs_2_bq_dag.bq_2022_tripdata_external_table_task scheduled__2023-06-14T00:00:00+00:00 [queued]>
[2023-06-15T15:26:34.037+0000] {taskinstance.py:1103} INFO - Dependencies all met for dep_context=requeueable deps ti=<TaskInstance: gcs_2_bq_dag.bq_2022_tripdata_external_table_task scheduled__2023-06-14T00:00:00+00:00 [queued]>
[2023-06-15T15:26:34.037+0000] {taskinstance.py:1308} INFO - Starting attempt 2 of 2
[2023-06-15T15:26:34.052+0000] {taskinstance.py:1327} INFO - Executing <Task(BigQueryCreateExternalTableOperator): bq_2022_tripdata_external_table_task> on 2023-06-14 00:00:00+00:00
[2023-06-15T15:26:34.059+0000] {standard_task_runner.py:57} INFO - Started process 1136 to run task
[2023-06-15T15:26:34.062+0000] {standard_task_runner.py:84} INFO - Running: ['***', 'tasks', 'run', 'gcs_2_bq_dag', 'bq_2022_tripdata_external_table_task', 'scheduled__2023-06-14T00:00:00+00:00', '--job-id', '493', '--raw', '--subdir', 'DAGS_FOLDER/gcs_to_bq.py', '--cfg-path', '/tmp/tmpvspwj0se']
[2023-06-15T15:26:34.064+0000] {standard_task_runner.py:85} INFO - Job 493: Subtask bq_2022_tripdata_external_table_task
[2023-06-15T15:26:34.116+0000] {task_command.py:410} INFO - Running <TaskInstance: gcs_2_bq_dag.bq_2022_tripdata_external_table_task scheduled__2023-06-14T00:00:00+00:00 [running]> on host 659e337ed365
[2023-06-15T15:26:34.203+0000] {taskinstance.py:1545} INFO - Exporting env vars: AIRFLOW_CTX_DAG_OWNER='***' AIRFLOW_CTX_DAG_ID='gcs_2_bq_dag' AIRFLOW_CTX_TASK_ID='bq_2022_tripdata_external_table_task' AIRFLOW_CTX_EXECUTION_DATE='2023-06-14T00:00:00+00:00' AIRFLOW_CTX_TRY_NUMBER='2' AIRFLOW_CTX_DAG_RUN_ID='scheduled__2023-06-14T00:00:00+00:00'
[2023-06-15T15:26:34.225+0000] {taskinstance.py:1824} ERROR - Task failed with exception
Traceback (most recent call last):
  File "/home/airflow/.local/lib/python3.9/site-packages/airflow/providers/google/cloud/operators/bigquery.py", line 1606, in execute
    bq_hook = BigQueryHook(
  File "/home/airflow/.local/lib/python3.9/site-packages/airflow/providers/google/cloud/hooks/bigquery.py", line 105, in __init__
    super().__init__(
  File "/home/airflow/.local/lib/python3.9/site-packages/airflow/providers/google/common/hooks/base_google.py", line 234, in __init__
    self.extras: dict = self.get_connection(self.gcp_conn_id).extra_dejson
  File "/home/airflow/.local/lib/python3.9/site-packages/airflow/hooks/base.py", line 72, in get_connection
    conn = Connection.get_connection_from_secrets(conn_id)
  File "/home/airflow/.local/lib/python3.9/site-packages/airflow/models/connection.py", line 434, in get_connection_from_secrets
    raise AirflowNotFoundException(f"The conn_id `{conn_id}` isn't defined")
airflow.exceptions.AirflowNotFoundException: The conn_id `google_cloud_default` isn't defined
[2023-06-15T15:26:34.230+0000] {taskinstance.py:1345} INFO - Marking task as FAILED. dag_id=gcs_2_bq_dag, task_id=bq_2022_tripdata_external_table_task, execution_date=20230614T000000, start_date=20230615T152634, end_date=20230615T152634
[2023-06-15T15:26:34.240+0000] {standard_task_runner.py:104} ERROR - Failed to execute job 493 for task bq_2022_tripdata_external_table_task (The conn_id `google_cloud_default` isn't defined; 1136)
[2023-06-15T15:26:34.273+0000] {local_task_job_runner.py:225} INFO - Task exited with return code 1
[2023-06-15T15:26:34.290+0000] {taskinstance.py:2651} INFO - 0 downstream tasks scheduled from follow-on schedule check
[2023-06-15T16:20:40.528+0000] {taskinstance.py:1103} INFO - Dependencies all met for dep_context=non-requeueable deps ti=<TaskInstance: gcs_2_bq_dag.bq_2022_tripdata_external_table_task scheduled__2023-06-14T00:00:00+00:00 [queued]>
[2023-06-15T16:20:40.576+0000] {taskinstance.py:1103} INFO - Dependencies all met for dep_context=requeueable deps ti=<TaskInstance: gcs_2_bq_dag.bq_2022_tripdata_external_table_task scheduled__2023-06-14T00:00:00+00:00 [queued]>
[2023-06-15T16:20:40.576+0000] {taskinstance.py:1308} INFO - Starting attempt 2 of 2
[2023-06-15T16:20:40.592+0000] {taskinstance.py:1327} INFO - Executing <Task(BigQueryCreateExternalTableOperator): bq_2022_tripdata_external_table_task> on 2023-06-14 00:00:00+00:00
[2023-06-15T16:20:40.599+0000] {standard_task_runner.py:57} INFO - Started process 1929 to run task
[2023-06-15T16:20:40.602+0000] {standard_task_runner.py:84} INFO - Running: ['***', 'tasks', 'run', 'gcs_2_bq_dag', 'bq_2022_tripdata_external_table_task', 'scheduled__2023-06-14T00:00:00+00:00', '--job-id', '517', '--raw', '--subdir', 'DAGS_FOLDER/gcs_to_bq.py', '--cfg-path', '/tmp/tmpoi108j4_']
[2023-06-15T16:20:40.604+0000] {standard_task_runner.py:85} INFO - Job 517: Subtask bq_2022_tripdata_external_table_task
[2023-06-15T16:20:40.644+0000] {task_command.py:410} INFO - Running <TaskInstance: gcs_2_bq_dag.bq_2022_tripdata_external_table_task scheduled__2023-06-14T00:00:00+00:00 [running]> on host 659e337ed365
[2023-06-15T16:20:40.707+0000] {taskinstance.py:1545} INFO - Exporting env vars: AIRFLOW_CTX_DAG_OWNER='***' AIRFLOW_CTX_DAG_ID='gcs_2_bq_dag' AIRFLOW_CTX_TASK_ID='bq_2022_tripdata_external_table_task' AIRFLOW_CTX_EXECUTION_DATE='2023-06-14T00:00:00+00:00' AIRFLOW_CTX_TRY_NUMBER='2' AIRFLOW_CTX_DAG_RUN_ID='scheduled__2023-06-14T00:00:00+00:00'
[2023-06-15T16:20:40.719+0000] {base.py:73} INFO - Using connection ID 'gcloud' for task execution.
[2023-06-15T16:20:43.557+0000] {taskinstance.py:1824} ERROR - Task failed with exception
Traceback (most recent call last):
  File "/home/airflow/.local/lib/python3.9/site-packages/airflow/providers/google/cloud/operators/bigquery.py", line 1612, in execute
    table = bq_hook.create_empty_table(
  File "/home/airflow/.local/lib/python3.9/site-packages/airflow/providers/google/common/hooks/base_google.py", line 468, in inner_wrapper
    return func(self, *args, **kwargs)
  File "/home/airflow/.local/lib/python3.9/site-packages/airflow/providers/google/cloud/hooks/bigquery.py", line 406, in create_empty_table
    return self.get_client(project_id=project_id, location=location).create_table(
  File "/home/airflow/.local/lib/python3.9/site-packages/google/cloud/bigquery/client.py", line 748, in create_table
    api_response = self._call_api(
  File "/home/airflow/.local/lib/python3.9/site-packages/google/cloud/bigquery/client.py", line 782, in _call_api
    return call()
  File "/home/airflow/.local/lib/python3.9/site-packages/google/api_core/retry.py", line 283, in retry_wrapped_func
    return retry_target(
  File "/home/airflow/.local/lib/python3.9/site-packages/google/api_core/retry.py", line 190, in retry_target
    return target()
  File "/home/airflow/.local/lib/python3.9/site-packages/google/cloud/_http/__init__.py", line 494, in api_request
    raise exceptions.from_http_response(response)
google.api_core.exceptions.BadRequest: 400 POST https://bigquery.googleapis.com/bigquery/v2/projects/dtc-de-382609/datasets/stock_table/tables?prettyPrint=false: Error while reading table: 2022_tripdata_external_table, error message: Failed to expand table 2022_tripdata_external_table with file pattern gs://dtc-de-382609_bucket/stock_data/2022/*: matched no files. File: gs://dtc-de-382609_bucket/stock_data/2022/*
[2023-06-15T16:20:43.567+0000] {taskinstance.py:1345} INFO - Marking task as FAILED. dag_id=gcs_2_bq_dag, task_id=bq_2022_tripdata_external_table_task, execution_date=20230614T000000, start_date=20230615T162040, end_date=20230615T162043
[2023-06-15T16:20:43.577+0000] {standard_task_runner.py:104} ERROR - Failed to execute job 517 for task bq_2022_tripdata_external_table_task (400 POST https://bigquery.googleapis.com/bigquery/v2/projects/dtc-de-382609/datasets/stock_table/tables?prettyPrint=false: Error while reading table: 2022_tripdata_external_table, error message: Failed to expand table 2022_tripdata_external_table with file pattern gs://dtc-de-382609_bucket/stock_data/2022/*: matched no files. File: gs://dtc-de-382609_bucket/stock_data/2022/*; 1929)
[2023-06-15T16:20:43.596+0000] {local_task_job_runner.py:225} INFO - Task exited with return code 1
[2023-06-15T16:20:43.611+0000] {taskinstance.py:2651} INFO - 0 downstream tasks scheduled from follow-on schedule check
