[2023-05-06T09:42:06.317+0000] {taskinstance.py:1125} INFO - Dependencies all met for dep_context=non-requeueable deps ti=<TaskInstance: upload_to_gcs.hello_world manual__2023-05-06T09:37:14.093752+00:00 [queued]>
[2023-05-06T09:42:06.509+0000] {taskinstance.py:1125} INFO - Dependencies all met for dep_context=requeueable deps ti=<TaskInstance: upload_to_gcs.hello_world manual__2023-05-06T09:37:14.093752+00:00 [queued]>
[2023-05-06T09:42:06.509+0000] {taskinstance.py:1331} INFO - Starting attempt 2 of 2
[2023-05-06T09:42:06.530+0000] {taskinstance.py:1350} INFO - Executing <Task(PythonOperator): hello_world> on 2023-05-06 09:37:14.093752+00:00
[2023-05-06T09:42:06.537+0000] {standard_task_runner.py:57} INFO - Started process 211 to run task
[2023-05-06T09:42:06.541+0000] {standard_task_runner.py:84} INFO - Running: ['***', 'tasks', 'run', 'upload_to_gcs', 'hello_world', 'manual__2023-05-06T09:37:14.093752+00:00', '--job-id', '10', '--raw', '--subdir', 'DAGS_FOLDER/upload_to_gcs.py', '--cfg-path', '/tmp/tmp33x_5bs_']
[2023-05-06T09:42:06.544+0000] {standard_task_runner.py:85} INFO - Job 10: Subtask hello_world
[2023-05-06T09:42:06.597+0000] {task_command.py:410} INFO - Running <TaskInstance: upload_to_gcs.hello_world manual__2023-05-06T09:37:14.093752+00:00 [running]> on host c32461df29f3
[2023-05-06T09:42:06.688+0000] {taskinstance.py:1570} INFO - Exporting env vars: AIRFLOW_CTX_DAG_OWNER='***' AIRFLOW_CTX_DAG_ID='upload_to_gcs' AIRFLOW_CTX_TASK_ID='hello_world' AIRFLOW_CTX_EXECUTION_DATE='2023-05-06T09:37:14.093752+00:00' AIRFLOW_CTX_TRY_NUMBER='2' AIRFLOW_CTX_DAG_RUN_ID='manual__2023-05-06T09:37:14.093752+00:00'
[2023-05-06T09:42:06.689+0000] {taskinstance.py:1847} ERROR - Task failed with exception
Traceback (most recent call last):
  File "/home/airflow/.local/lib/python3.7/site-packages/airflow/operators/python.py", line 181, in execute
    return_value = self.execute_callable()
  File "/home/airflow/.local/lib/python3.7/site-packages/airflow/operators/python.py", line 198, in execute_callable
    return self.python_callable(*self.op_args, **self.op_kwargs)
  File "/opt/airflow/dags/upload_to_gcs.py", line 33, in hello
    logging('Hello world')
TypeError: 'module' object is not callable
[2023-05-06T09:42:06.700+0000] {taskinstance.py:1373} INFO - Marking task as FAILED. dag_id=upload_to_gcs, task_id=hello_world, execution_date=20230506T093714, start_date=20230506T094206, end_date=20230506T094206
[2023-05-06T09:42:06.714+0000] {standard_task_runner.py:109} ERROR - Failed to execute job 10 for task hello_world ('module' object is not callable; 211)
[2023-05-06T09:42:06.752+0000] {local_task_job_runner.py:232} INFO - Task exited with return code 1
[2023-05-06T09:42:06.778+0000] {taskinstance.py:2674} INFO - 0 downstream tasks scheduled from follow-on schedule check
