[2023-06-15T14:14:42.982+0000] {taskinstance.py:1103} INFO - Dependencies all met for dep_context=non-requeueable deps ti=<TaskInstance: gcs_2_bq_dag.bq_2020_tripdata_external_table_task scheduled__2023-06-14T00:00:00+00:00 [queued]>
[2023-06-15T14:14:42.995+0000] {taskinstance.py:1103} INFO - Dependencies all met for dep_context=requeueable deps ti=<TaskInstance: gcs_2_bq_dag.bq_2020_tripdata_external_table_task scheduled__2023-06-14T00:00:00+00:00 [queued]>
[2023-06-15T14:14:42.995+0000] {taskinstance.py:1308} INFO - Starting attempt 2 of 2
[2023-06-15T14:14:43.014+0000] {taskinstance.py:1327} INFO - Executing <Task(BigQueryCreateExternalTableOperator): bq_2020_tripdata_external_table_task> on 2023-06-14 00:00:00+00:00
[2023-06-15T14:14:43.020+0000] {standard_task_runner.py:57} INFO - Started process 144 to run task
[2023-06-15T14:14:43.025+0000] {standard_task_runner.py:84} INFO - Running: ['***', 'tasks', 'run', 'gcs_2_bq_dag', 'bq_2020_tripdata_external_table_task', 'scheduled__2023-06-14T00:00:00+00:00', '--job-id', '477', '--raw', '--subdir', 'DAGS_FOLDER/gcs_to_bq.py', '--cfg-path', '/tmp/tmptyp5t0j6']
[2023-06-15T14:14:43.028+0000] {standard_task_runner.py:85} INFO - Job 477: Subtask bq_2020_tripdata_external_table_task
[2023-06-15T14:14:43.085+0000] {task_command.py:410} INFO - Running <TaskInstance: gcs_2_bq_dag.bq_2020_tripdata_external_table_task scheduled__2023-06-14T00:00:00+00:00 [running]> on host 659e337ed365
[2023-06-15T14:14:43.186+0000] {taskinstance.py:1545} INFO - Exporting env vars: AIRFLOW_CTX_DAG_OWNER='***' AIRFLOW_CTX_DAG_ID='gcs_2_bq_dag' AIRFLOW_CTX_TASK_ID='bq_2020_tripdata_external_table_task' AIRFLOW_CTX_EXECUTION_DATE='2023-06-14T00:00:00+00:00' AIRFLOW_CTX_TRY_NUMBER='2' AIRFLOW_CTX_DAG_RUN_ID='scheduled__2023-06-14T00:00:00+00:00'
[2023-06-15T14:14:43.217+0000] {taskinstance.py:1824} ERROR - Task failed with exception
Traceback (most recent call last):
  File "/home/airflow/.local/lib/python3.9/site-packages/airflow/providers/google/cloud/operators/bigquery.py", line 1606, in execute
    bq_hook = BigQueryHook(
  File "/home/airflow/.local/lib/python3.9/site-packages/airflow/providers/google/cloud/hooks/bigquery.py", line 105, in __init__
    super().__init__(
  File "/home/airflow/.local/lib/python3.9/site-packages/airflow/providers/google/common/hooks/base_google.py", line 234, in __init__
    self.extras: dict = self.get_connection(self.gcp_conn_id).extra_dejson
  File "/home/airflow/.local/lib/python3.9/site-packages/airflow/hooks/base.py", line 72, in get_connection
    conn = Connection.get_connection_from_secrets(conn_id)
  File "/home/airflow/.local/lib/python3.9/site-packages/airflow/models/connection.py", line 434, in get_connection_from_secrets
    raise AirflowNotFoundException(f"The conn_id `{conn_id}` isn't defined")
airflow.exceptions.AirflowNotFoundException: The conn_id `google_cloud_default` isn't defined
[2023-06-15T14:14:43.226+0000] {taskinstance.py:1345} INFO - Marking task as FAILED. dag_id=gcs_2_bq_dag, task_id=bq_2020_tripdata_external_table_task, execution_date=20230614T000000, start_date=20230615T141442, end_date=20230615T141443
[2023-06-15T14:14:43.245+0000] {standard_task_runner.py:104} ERROR - Failed to execute job 477 for task bq_2020_tripdata_external_table_task (The conn_id `google_cloud_default` isn't defined; 144)
[2023-06-15T14:14:43.278+0000] {local_task_job_runner.py:225} INFO - Task exited with return code 1
[2023-06-15T14:14:43.301+0000] {taskinstance.py:2651} INFO - 0 downstream tasks scheduled from follow-on schedule check
[2023-06-15T15:26:34.018+0000] {taskinstance.py:1103} INFO - Dependencies all met for dep_context=non-requeueable deps ti=<TaskInstance: gcs_2_bq_dag.bq_2020_tripdata_external_table_task scheduled__2023-06-14T00:00:00+00:00 [queued]>
[2023-06-15T15:26:34.029+0000] {taskinstance.py:1103} INFO - Dependencies all met for dep_context=requeueable deps ti=<TaskInstance: gcs_2_bq_dag.bq_2020_tripdata_external_table_task scheduled__2023-06-14T00:00:00+00:00 [queued]>
[2023-06-15T15:26:34.029+0000] {taskinstance.py:1308} INFO - Starting attempt 2 of 2
[2023-06-15T15:26:34.041+0000] {taskinstance.py:1327} INFO - Executing <Task(BigQueryCreateExternalTableOperator): bq_2020_tripdata_external_table_task> on 2023-06-14 00:00:00+00:00
[2023-06-15T15:26:34.047+0000] {standard_task_runner.py:57} INFO - Started process 1134 to run task
[2023-06-15T15:26:34.050+0000] {standard_task_runner.py:84} INFO - Running: ['***', 'tasks', 'run', 'gcs_2_bq_dag', 'bq_2020_tripdata_external_table_task', 'scheduled__2023-06-14T00:00:00+00:00', '--job-id', '492', '--raw', '--subdir', 'DAGS_FOLDER/gcs_to_bq.py', '--cfg-path', '/tmp/tmpfuim1kih']
[2023-06-15T15:26:34.052+0000] {standard_task_runner.py:85} INFO - Job 492: Subtask bq_2020_tripdata_external_table_task
[2023-06-15T15:26:34.102+0000] {task_command.py:410} INFO - Running <TaskInstance: gcs_2_bq_dag.bq_2020_tripdata_external_table_task scheduled__2023-06-14T00:00:00+00:00 [running]> on host 659e337ed365
[2023-06-15T15:26:34.179+0000] {taskinstance.py:1545} INFO - Exporting env vars: AIRFLOW_CTX_DAG_OWNER='***' AIRFLOW_CTX_DAG_ID='gcs_2_bq_dag' AIRFLOW_CTX_TASK_ID='bq_2020_tripdata_external_table_task' AIRFLOW_CTX_EXECUTION_DATE='2023-06-14T00:00:00+00:00' AIRFLOW_CTX_TRY_NUMBER='2' AIRFLOW_CTX_DAG_RUN_ID='scheduled__2023-06-14T00:00:00+00:00'
[2023-06-15T15:26:34.200+0000] {taskinstance.py:1824} ERROR - Task failed with exception
Traceback (most recent call last):
  File "/home/airflow/.local/lib/python3.9/site-packages/airflow/providers/google/cloud/operators/bigquery.py", line 1606, in execute
    bq_hook = BigQueryHook(
  File "/home/airflow/.local/lib/python3.9/site-packages/airflow/providers/google/cloud/hooks/bigquery.py", line 105, in __init__
    super().__init__(
  File "/home/airflow/.local/lib/python3.9/site-packages/airflow/providers/google/common/hooks/base_google.py", line 234, in __init__
    self.extras: dict = self.get_connection(self.gcp_conn_id).extra_dejson
  File "/home/airflow/.local/lib/python3.9/site-packages/airflow/hooks/base.py", line 72, in get_connection
    conn = Connection.get_connection_from_secrets(conn_id)
  File "/home/airflow/.local/lib/python3.9/site-packages/airflow/models/connection.py", line 434, in get_connection_from_secrets
    raise AirflowNotFoundException(f"The conn_id `{conn_id}` isn't defined")
airflow.exceptions.AirflowNotFoundException: The conn_id `google_cloud_default` isn't defined
[2023-06-15T15:26:34.206+0000] {taskinstance.py:1345} INFO - Marking task as FAILED. dag_id=gcs_2_bq_dag, task_id=bq_2020_tripdata_external_table_task, execution_date=20230614T000000, start_date=20230615T152634, end_date=20230615T152634
[2023-06-15T15:26:34.220+0000] {standard_task_runner.py:104} ERROR - Failed to execute job 492 for task bq_2020_tripdata_external_table_task (The conn_id `google_cloud_default` isn't defined; 1134)
[2023-06-15T15:26:34.261+0000] {local_task_job_runner.py:225} INFO - Task exited with return code 1
[2023-06-15T15:26:34.275+0000] {taskinstance.py:2651} INFO - 0 downstream tasks scheduled from follow-on schedule check
[2023-06-15T16:20:40.459+0000] {taskinstance.py:1103} INFO - Dependencies all met for dep_context=non-requeueable deps ti=<TaskInstance: gcs_2_bq_dag.bq_2020_tripdata_external_table_task scheduled__2023-06-14T00:00:00+00:00 [queued]>
[2023-06-15T16:20:40.469+0000] {taskinstance.py:1103} INFO - Dependencies all met for dep_context=requeueable deps ti=<TaskInstance: gcs_2_bq_dag.bq_2020_tripdata_external_table_task scheduled__2023-06-14T00:00:00+00:00 [queued]>
[2023-06-15T16:20:40.469+0000] {taskinstance.py:1308} INFO - Starting attempt 2 of 2
[2023-06-15T16:20:40.480+0000] {taskinstance.py:1327} INFO - Executing <Task(BigQueryCreateExternalTableOperator): bq_2020_tripdata_external_table_task> on 2023-06-14 00:00:00+00:00
[2023-06-15T16:20:40.486+0000] {standard_task_runner.py:57} INFO - Started process 1928 to run task
[2023-06-15T16:20:40.488+0000] {standard_task_runner.py:84} INFO - Running: ['***', 'tasks', 'run', 'gcs_2_bq_dag', 'bq_2020_tripdata_external_table_task', 'scheduled__2023-06-14T00:00:00+00:00', '--job-id', '516', '--raw', '--subdir', 'DAGS_FOLDER/gcs_to_bq.py', '--cfg-path', '/tmp/tmpzz0fbwrf']
[2023-06-15T16:20:40.491+0000] {standard_task_runner.py:85} INFO - Job 516: Subtask bq_2020_tripdata_external_table_task
[2023-06-15T16:20:40.530+0000] {task_command.py:410} INFO - Running <TaskInstance: gcs_2_bq_dag.bq_2020_tripdata_external_table_task scheduled__2023-06-14T00:00:00+00:00 [running]> on host 659e337ed365
[2023-06-15T16:20:40.617+0000] {taskinstance.py:1545} INFO - Exporting env vars: AIRFLOW_CTX_DAG_OWNER='***' AIRFLOW_CTX_DAG_ID='gcs_2_bq_dag' AIRFLOW_CTX_TASK_ID='bq_2020_tripdata_external_table_task' AIRFLOW_CTX_EXECUTION_DATE='2023-06-14T00:00:00+00:00' AIRFLOW_CTX_TRY_NUMBER='2' AIRFLOW_CTX_DAG_RUN_ID='scheduled__2023-06-14T00:00:00+00:00'
[2023-06-15T16:20:40.634+0000] {base.py:73} INFO - Using connection ID 'gcloud' for task execution.
[2023-06-15T16:20:43.557+0000] {taskinstance.py:1824} ERROR - Task failed with exception
Traceback (most recent call last):
  File "/home/airflow/.local/lib/python3.9/site-packages/airflow/providers/google/cloud/operators/bigquery.py", line 1612, in execute
    table = bq_hook.create_empty_table(
  File "/home/airflow/.local/lib/python3.9/site-packages/airflow/providers/google/common/hooks/base_google.py", line 468, in inner_wrapper
    return func(self, *args, **kwargs)
  File "/home/airflow/.local/lib/python3.9/site-packages/airflow/providers/google/cloud/hooks/bigquery.py", line 406, in create_empty_table
    return self.get_client(project_id=project_id, location=location).create_table(
  File "/home/airflow/.local/lib/python3.9/site-packages/google/cloud/bigquery/client.py", line 748, in create_table
    api_response = self._call_api(
  File "/home/airflow/.local/lib/python3.9/site-packages/google/cloud/bigquery/client.py", line 782, in _call_api
    return call()
  File "/home/airflow/.local/lib/python3.9/site-packages/google/api_core/retry.py", line 283, in retry_wrapped_func
    return retry_target(
  File "/home/airflow/.local/lib/python3.9/site-packages/google/api_core/retry.py", line 190, in retry_target
    return target()
  File "/home/airflow/.local/lib/python3.9/site-packages/google/cloud/_http/__init__.py", line 494, in api_request
    raise exceptions.from_http_response(response)
google.api_core.exceptions.BadRequest: 400 POST https://bigquery.googleapis.com/bigquery/v2/projects/dtc-de-382609/datasets/stock_table/tables?prettyPrint=false: Error while reading table: 2020_tripdata_external_table, error message: Failed to expand table 2020_tripdata_external_table with file pattern gs://dtc-de-382609_bucket/stock_data/2020/*: matched no files. File: gs://dtc-de-382609_bucket/stock_data/2020/*
[2023-06-15T16:20:43.567+0000] {taskinstance.py:1345} INFO - Marking task as FAILED. dag_id=gcs_2_bq_dag, task_id=bq_2020_tripdata_external_table_task, execution_date=20230614T000000, start_date=20230615T162040, end_date=20230615T162043
[2023-06-15T16:20:43.583+0000] {standard_task_runner.py:104} ERROR - Failed to execute job 516 for task bq_2020_tripdata_external_table_task (400 POST https://bigquery.googleapis.com/bigquery/v2/projects/dtc-de-382609/datasets/stock_table/tables?prettyPrint=false: Error while reading table: 2020_tripdata_external_table, error message: Failed to expand table 2020_tripdata_external_table with file pattern gs://dtc-de-382609_bucket/stock_data/2020/*: matched no files. File: gs://dtc-de-382609_bucket/stock_data/2020/*; 1928)
[2023-06-15T16:20:43.600+0000] {local_task_job_runner.py:225} INFO - Task exited with return code 1
[2023-06-15T16:20:43.621+0000] {taskinstance.py:2651} INFO - 0 downstream tasks scheduled from follow-on schedule check
